Workbook

Sheet README
A1: Financial & NFR Workbook: CloudScale AIOps Auto-Healing Platform (Pod 2)
A2: Capstone Artifact 4: 3-year TCO, token economics & model routing, NFR SLA matrix.
A4: Formulas from the Capstone brief (§4, Artifact 4)
A5: TCO = Compute_infra + Token_cost + Ops_overhead
A6: Token_cost = N_requests × ((T_in × P_in) + (T_out × P_out)) × (1 − Cache_ratio)
A7: Metrics tracked (brief §2): T_lat (latency per task) · Tokens/sec · CR (cache hit ratio) · FR (tool failure rate) · HITL when confidence C < 0.85 · NFR targets p95 < 3.5 s, availability 99.9%.
A9: Headline results (active scenario, live formulas)
A10: Active scenario | B10: =Assumptions!$B$5
A11: 3-year TCO | B11: ='TCO & ROI'!E30
A12: 3-year benefits | B12: ='TCO & ROI'!E37
A13: 3-year ROI | B13: ='TCO & ROI'!$B$45
A14: NPV of net benefit | B14: ='TCO & ROI'!$B$46
A15: Payback (months) | B15: ='TCO & ROI'!$B$48
A16: Token optimisation savings (ADR 03) | B16: ='Token Economics'!$B$25
A17: Token_cost share of 3-year TCO | B17: ='TCO & ROI'!$B$50
A18: Break-even P1 downtime cost ($/h) | B18: ='TCO & ROI'!$B$61
A19: NFRs met / not met / not measured | B19: ='NFR SLA Matrix'!G21&" / "&'NFR SLA Matrix'!G22&" / "&'NFR SLA Matrix'!G23
A21: How to use
A22: Assumptions | C22: Change blue inputs; yellow cells are the key levers. Switch the scenario in Assumptions!B5.
A23: Token Economics | C23: Per-task workload and routing table. Change Tier (Tier 1 / Tier 2) or Cache_ratio per task to test routing decisions; the brief's Token_cost formula is applied on every row.
A24: TCO & ROI | C24: 3-year roll-up with the brief's TCO formula, benefits, ROI, NPV, payback, and a side-by-side scenario sensitivity with break-even downtime cost.
A25: NFR SLA Matrix | C25: Targets vs. measured prototype values; status is computed (MET / NOT MET / NOT MEASURED).
A27: Legend
A28: 1,200 | C28: Blue: hardcoded input (change freely)
A29: 0.30 | C29: Yellow fill: key lever / scenario assumption
A30: =B5*12 | C30: Black: formula on the same sheet
A31: =Assumptions!B19 | C31: Green: link to another sheet
A33: Caveats
A34: • Volumes, downtime cost, MTTR reduction and coverage are Pod assumptions, not CloudScale data. Replace with Finance/SRE figures.
A35: • Model and cloud prices are list prices at the time of writing; verify before presenting.
A36: • Prototype measurements use a deterministic MockLLM and simulated clusters; latency and token figures must be re-measured with real models.
A37: • Benefits exclude harder-to-quantify items (retention of on-call staff, SLA penalties avoided beyond downtime cost, audit effort saved).

Sheet Assumptions
A1: Assumptions & Inputs: Pod 2 AIOps Auto-Healing Platform
A2: Blue text = input you can change · Yellow fill = key lever · Black = formula · Green = link from another sheet. Every hardcoded number has its source or rationale in the last column.
A4: 1. Scenario selector
A5: Active scenario (choose Conservative / Base / Optimistic) | B5: Base | G5: Drives column E of the lever table below; every sheet recalculates.
A7: 2. Key levers by scenario (these drive the ROI)
A8: Parameter | B8: Conservative | C8: Base | D8: Optimistic | E8: Active | F8: Unit | G8: Source / rationale
A9: Incidents fully auto-remediated (READ / NON_DESTRUCTIVE, C ≥ 0.85) | B9: 0.2 | C9: 0.3 | D9: 0.4 | E9: =INDEX($B9:$D9,MATCH($B$5,$B$8:$D$8,0)) | F9: % of incidents | G9: Pod assumption. Prototype demo: 2 of 6 incidents auto-remediated (stale-cache ×2).
A10: Incidents HITL-assisted (DESTRUCTIVE, SRE-approved) | B10: 0.25 | C10: 0.3 | D10: 0.35 | E10: =INDEX($B10:$D10,MATCH($B$5,$B$8:$D$8,0)) | F10: % of incidents | G10: Pod assumption. Prototype demo: 3 of 6 incidents approved via the HITL gate.
A11: MTTR reduction on covered incidents | B11: 0.3 | C11: 0.4 | D11: 0.55 | E11: =INDEX($B11:$D11,MATCH($B$5,$B$8:$D$8,0)) | F11: % | G11: Pod assumption: triage + RCA + plan drafted in minutes instead of manual diagnosis; validate in pilot.
A12: Business cost of one P1 hour | B12: 5000 | C12: 8000 | D12: 15000 | E12: =INDEX($B12:$D12,MATCH($B$5,$B$8:$D$8,0)) | F12: $ / hour | G12: Pod assumption (revenue loss + SLA credits). CloudScale Finance to confirm; most sensitive input.
A13: Share of MTTR gain attributed to this platform | B13: 0.4 | C13: 0.5 | D13: 0.6 | E13: =INDEX($B13:$D13,MATCH($B$5,$B$8:$D$8,0)) | F13: % | G13: Conservatism factor: part of any MTTR gain comes from other process changes.
A14: Responder toil reduction on covered incidents | B14: 0.3 | C14: 0.4 | D14: 0.55 | E14: =INDEX($B14:$D14,MATCH($B$5,$B$8:$D$8,0)) | F14: % | G14: Pod assumption: fewer engineers paged, diagnostics pre-collected by the Triage agent.
A15: Human-reviewed alerts auto-triaged / de-duplicated | B15: 0.45 | C15: 0.6 | D15: 0.75 | E15: =INDEX($B15:$D15,MATCH($B$5,$B$8:$D$8,0)) | F15: % | G15: Pod assumption: alert-storm de-duplication via classification + semantic cache (ADR 03).
A16: Soft-savings realisation (freed hours turned into value) | B16: 0.35 | C16: 0.5 | D16: 0.65 | E16: =INDEX($B16:$D16,MATCH($B$5,$B$8:$D$8,0)) | F16: % | G16: Freed engineer time is capacity, not cash: only this share is counted in toil and alert-triage benefits.
A18: 3. Volume & operations (Year 1 baseline)
A19: Parameter | B19: Value | C19: Unit | G19: Source / rationale
A20: Monitoring alerts per month (Prometheus / Datadog / CloudWatch) | B20: 150000 | C20: alerts / month | G20: Pod assumption for a global multi-cloud estate (AWS + Azure).
A21: Actionable incidents per month (all severities) | B21: 600 | C21: incidents / month | G21: Pod assumption: incidents that need diagnosis and a remediation decision.
A22: Share of incidents that are P1 / P2 | B22: 0.1 | C22: % | G22: Pod assumption; brief targets P1/P2 MTTR.
A23: P1 share within P1 / P2 incidents | B23: 0.25 | C23: % | G23: Pod assumption.
A24: Annual growth in alert and incident volume | B24: 0.15 | C24: % / year | G24: Pod assumption (estate growth).
A25: Share of alerts that need a human look today | B25: 0.15 | C25: % | G25: Pod assumption; the rest are auto-closed or ignored.
A26: Minutes per human-reviewed alert | B26: 2 | C26: minutes | G26: Pod assumption.
A27: Baseline MTTR, P1 | B27: 3 | C27: hours | G27: Pod assumption (current state, manual diagnosis).
A28: Baseline MTTR, P2 | B28: 6 | C28: hours | G28: Pod assumption (current state).
A29: P2 business impact relative to a P1 hour | B29: 0.1 | C29: x of P1 cost | G29: Pod assumption: P2 = degraded service, not outage.
A30: Responder hours per incident (all engineers involved) | B30: 3 | C30: hours | G30: Pod assumption.
A31: Loaded SRE cost per hour | B31: 95 | C31: $ / hour | G31: Equals $190k loaded FTE / ~2,000 h. Pod assumption.
... A40: Provisioned LLM throughput quota | B40: 20000 | C40: tokens / sec | G40: Pod assumption (provider rate limit to request); checked in NFR matrix.
A42: 4. LLM pricing ($ per 1M tokens)
A43: Parameter | B43: Value | C43: Unit | G43: Source / rationale
A44: Tier 1 (small/fast, e.g. GPT-4o-mini): input | B44: 0.15 | C44: $ / 1M tokens | G44: Provider list price used for this model; verify current pricing before presenting.
A45: Tier 1: output | B45: 0.6 | C45: $ / 1M tokens | G45: As above.
A46: Tier 2 (large/reasoning, e.g. GPT-4o): input | B46: 2.5 | C46: $ / 1M tokens | G46: As above.
A47: Tier 2: output | B47: 10 | C47: $ / 1M tokens | G47: As above.
A48: Embeddings for semantic cache (e.g. text-embedding-3-small) | B48: 0.02 | C48: $ / 1M tokens | G48: As above.
A50: 5. Compute_infra components (monthly, Year 1)
A51: Component | B51: Qty | C51: Unit cost ($) | D51: Hours / month | E51: Monthly cost ($) | F51: Basis | G51: Source / rationale
A52: Amazon EKS control plane (agent runtime cluster) | B52: 1 | C52: 0.1 | D52: 730 | E52: =B52*C52*D52 | F52: per hour | G52: AWS EKS list price $0.10/cluster-hour.
A53: EKS worker nodes (m6i.xlarge): orchestrator, MCP server, OPA, LiteLLM | B53: 4 | C53: 0.192 | D53: 730 | E53: =B53*C53*D53 | F53: per hour | G53: AWS on-demand list price (us-east-1, approx.); verify at aws.amazon.com/pricing.
...

Sheet Token Economics
A1: Token Economics & Model Routing
A2: Token_cost = N_requests × ((T_in × P_in) + (T_out × P_out)) × (1 − Cache_ratio)
A3: Formula as given in the Capstone brief, §4 Artifact 4. Applied per task row; prices are per 1M tokens, so each row divides by 1,000,000. Optimized Tier-1 prices include the Tier-2 escalation surcharge.
A5: Alerts per month | B5: =Assumptions!$B$20
A6: Incidents per month | B6: =Assumptions!$B$21
A7: Tier-1 → Tier-2 escalation rate | B7: =Assumptions!$B$38
A8: Workload profile | G8: BASELINE: all Tier 2, no cache | L8: OPTIMIZED: tiered routing + semantic cache (ADR 03)
A9: Task (agent step) | B9: Unit of work | C9: Calls per unit | D9: T_in (tokens / call) | E9: T_out (tokens / call) | F9: N_requests / month | G9: Tier | H9: P_in ($/1M) | I9: P_out ($/1M) | J9: Cache_ratio | K9: Token_cost ($/mo) | L9: Tier | M9: P_in eff. ($/1M) | N9: P_out eff. ($/1M) | O9: Cache_ratio | P9: Token_cost ($/mo) | Q9: Savings ($/mo) | R9: Raw tokens / mo | S9: Billed tokens / mo (opt.) | T9: Routing rationale
A10: Alert classification (classify) | B10: alert | C10: 1 | D10: 700 | E10: 80 | F10: =IF(B10="alert",$B$5,$B$6)*C10 | G10: Tier 2 | H10: =IF(G10="Tier 2",Assumptions!$B$46,IF(G10="Tier 1",Assumptions!$B$44,0)) | I10: =IF(G10="Tier 2",Assumptions!$B$47,IF(G10="Tier 1",Assumptions!$B$45,0)) | J10: 0 | K10: =F10*((D10*H10)+(E10*I10))/1000000*(1-J10) | L10: Tier 1 | M10: =IF(L10="Tier 1",Assumptions!$B$44+$B$7*Assumptions!$B$46,IF(L10="Tier 2",Assumptions!$B$46,IF(L10="Embedding",Assumptions!$B$48,0))) | N10: =IF(L10="Tier 1",Assumptions!$B$45+$B$7*Assumptions!$B$47,IF(L10="Tier 2",Assumptions!$B$47,0)) | O10: 0.55 | P10: =F10*((D10*M10)+(E10*N10))/1000000*(1-O10) | Q10: =K10-P10 | R10: =F10*(D10+E10) | S10: =R10*(1-O10) | T10: Short, repetitive prompt; cached per alert rule (alert storms).
A11: Alert de-duplication & correlation (Supervisor) | B11: alert | C11: 1 | D11: 1200 | E11: 120 | F11: =IF(B11="alert",$B$5,$B$6)*C11 | G11: Tier 2 | H11: =IF(G11="Tier 2",Assumptions!$B$46,IF(G11="Tier 1",Assumptions!$B$44,0)) | I11: =IF(G11="Tier 2",Assumptions!$B$47,IF(G11="Tier 1",Assumptions!$B$45,0)) | J11: 0 | K11: =F11*((D11*H11)+(E11*I11))/1000000*(1-J11) | L11: Tier 1 | M11: =IF(L11="Tier 1",Assumptions!$B$44+$B$7*Assumptions!$B$46,IF(L11="Tier 2",Assumptions!$B$46,IF(L11="Embedding",Assumptions!$B$48,0))) | N11: =IF(L11="Tier 1",Assumptions!$B$45+$B$7*Assumptions!$B$47,IF(L11="Tier 2",Assumptions!$B$47,0)) | O11: 0.4 | P11: =F11*((D11*M11)+(E11*N11))/1000000*(1-O11) | Q11: =K11-P11 | R11: =F11*(D11+E11) | S11: =R11*(1-O11) | T11: Pattern matching over recent alerts; Tier 1 is sufficient.
A12: Input guardrail L2 (LlamaGuard-class check) | B12: incident | C12: 1 | D12: 7000 | E12: 20 | F12: =IF(B12="alert",$B$5,$B$6)*C12 | G12: Tier 2 | H12: =IF(G12="Tier 2",Assumptions!$B$46,IF(G12="Tier 1",Assumptions!$B$44,0)) | I12: =IF(G12="Tier 2",Assumptions!$B$47,IF(G12="Tier 1",Assumptions!$B$45,0)) | J12: 0 | K12: =F12*((D12*H12)+(E12*I12))/1000000*(1-J12) | L12: Tier 1 | M12: =IF(L12="Tier 1",Assumptions!$B$44+$B$7*Assumptions!$B$46,IF(L12="Tier 2",Assumptions!$B$46,IF(L12="Embedding",Assumptions!$B$48,0))) | N12: =IF(L12="Tier 1",Assumptions!$B$45+$B$7*Assumptions!$B$47,IF(L12="Tier 2",Assumptions!$B$47,0)) | O12: 0 | P12: =F12*((D12*M12)+(E12*N12))/1000000*(1-O12) | Q12: =K12-P12 | R12: =F12*(D12+E12) | S12: =R12*(1-O12) | T12: Runs once per untrusted input, not per agent hop (ADR 03).
A13: Log summarisation (Triage: summarize_logs) | B13: incident | C13: 4 | D13: 8000 | E13: 600 | F13: =IF(B13="alert",$B$5,$B$6)*C13 | G13: Tier 2 | H13: =IF(G13="Tier 2",Assumptions!$B$46,IF(G13="Tier 1",Assumptions!$B$44,0)) | I13: =IF(G13="Tier 2",Assumptions!$B$47,IF(G13="Tier 1",Assumptions!$B$45,0)) | J13: 0 | K13: =F13*((D13*H13)+(E13*I13))/1000000*(1-J13) | L13: Tier 1 | M13: =IF(L13="Tier 1",Assumptions!$B$44+$B$7*Assumptions!$B$46,IF(L13="Tier 2",Assumptions!$B$46,IF(L13="Embedding",Assumptions!$B$48,0))) | N13: =IF(L13="Tier 1",Assumptions!$B$45+$B$7*Assumptions!$B$47,IF(L13="Tier 2",Assumptions!$B$47,0)) | O13: 0.35 | P13: =F13*((D13*M13)+(E13*N13))/1000000*(1-O13) | Q13: =K13-P13 | R13: =F13*(D13+E13) | S13: =R13*(1-O13) | T13: High volume, low reasoning; cached on log fingerprint.
A14: Root-cause analysis (Triage: rca, tool loop) | B14: incident | C14: 6 | D14: 12000 | E14: 800 | F14: =IF(B14="alert",$B$5,$B$6)*C14 | G14: Tier 2 | H14: =IF(G14="Tier 2",Assumptions!$B$46,IF(G14="Tier 1",Assumptions!$B$44,0)) | I14: =IF(G14="Tier 2",Assumptions!$B$47,IF(G14="Tier 1",Assumptions!$B$45,0)) | J14: 0 | K14: =F14*((D14*H14)+(E14*I14))/1000000*(1-J14) | L14: Tier 2 | M14: =IF(L14="Tier 1",Assumptions!$B$44+$B$7*Assumptions!$B$46,IF(L14="Tier 2",Assumptions!$B$46,IF(L14="Embedding",Assumptions!$B$48,0))) | N14: =IF(L14="Tier 1",Assumptions!$B$45+$B$7*Assumptions!$B$47,IF(L14="Tier 2",Assumptions!$B$47,0)) | O14: 0.3 | P14: =F14*((D14*M14)+(E14*N14))/1000000*(1-O14) | Q14: =K14-P14 | R14: =F14*(D14+E14) | S14: =R14*(1-O14) | T14: Hard multi-signal reasoning stays on Tier 2; repeat incidents hit cache.
A15: Remediation plan + rollback (Planner) | B15: incident | C15: 1 | D15: 5000 | E15: 1500 | F15: =IF(B15="alert",$B$5,$B$6)*C15 | G15: Tier 2 | H15: =IF(G15="Tier 2",Assumptions!$B$46,IF(G15="Tier 1",Assumptions!$B$44,0)) | I15: =IF(G15="Tier 2",Assumptions!$B$47,IF(G15="Tier 1",Assumptions!$B$45,0)) | J15: 0 | K15: =F15*((D15*H15)+(E15*I15))/1000000*(1-J15) | L15: Tier 2 | M15: =IF(L15="Tier 1",Assumptions!$B$44+$B$7*Assumptions!$B$46,IF(L15="Tier 2",Assumptions!$B$46,IF(L15="Embedding",Assumptions!$B$48,0))) | N15: =IF(L15="Tier 1",Assumptions!$B$45+$B$7*Assumptions!$B$47,IF(L15="Tier 2",Assumptions!$B$47,0)) | O15: 0 | P15: =F15*((D15*M15)+(E15*N15))/1000000*(1-O15) | Q15: =K15-P15 | R15: =F15*(D15+E15) | S15: =R15*(1-O15) | T15: Never cached, never downgraded: this step writes production changes.
A16: Supervisor routing & budget checks | B16: incident | C16: 4 | D16: 2000 | E16: 150 | F16: =IF(B16="alert",$B$5,$B$6)*C16 | G16: Tier 2 | H16: =IF(G16="Tier 2",Assumptions!$B$46,IF(G16="Tier 1",Assumptions!$B$44,0)) | I16: =IF(G16="Tier 2",Assumptions!$B$47,IF(G16="Tier 1",Assumptions!$B$45,0)) | J16: 0 | K16: =F16*((D16*H16)+(E16*I16))/1000000*(1-J16) | L16: Tier 1 | M16: =IF(L16="Tier 1",Assumptions!$B$44+$B$7*Assumptions!$B$46,IF(L16="Tier 2",Assumptions!$B$46,IF(L16="Embedding",Assumptions!$B$48,0))) | N16: =IF(L16="Tier 1",Assumptions!$B$45+$B$7*Assumptions!$B$47,IF(L16="Tier 2",Assumptions!$B$47,0)) | O16: 0 | P16: =F16*((D16*M16)+(E16*N16))/1000000*(1-O16) | Q16: =K16-P16 | R16: =F16*(D16+E16) | S16: =R16*(1-O16) | T16: Simple routing decisions.
A17: Post-fix verification (Verifier) | B17: incident | C17: 2 | D17: 1500 | E17: 200 | F17: =IF(B17="alert",$B$5,$B$6)*C17 | G17: Tier 2 | H17: =IF(G17="Tier 2",Assumptions!$B$46,IF(G17="Tier 1",Assumptions!$B$44,0)) | I17: =IF(G17="Tier 2",Assumptions!$B$47,IF(G17="Tier 1",Assumptions!$B$45,0)) | J17: 0 | K17: =F17*((D17*H17)+(E17*I17))/1000000*(1-J17) | L17: Tier 1 | M17: =IF(L17="Tier 1",Assumptions!$B$44+$B$7*Assumptions!$B$46,IF(L17="Tier 2",Assumptions!$B$46,IF(L17="Embedding",Assumptions!$B$48,0))) | N17: =IF(L17="Tier 1",Assumptions!$B$45+$B$7*Assumptions!$B$47,IF(L17="Tier 2",Assumptions!$B$47,0)) | O17: 0 | P17: =F17*((D17*M17)+(E17*N17))/1000000*(1-O17) | Q17: =K17-P17 | R17: =F17*(D17+E17) | S17: =R17*(1-O17) | T17: Health-signal interpretation.
A18: Semantic-cache embedding lookups | B18: lookup | C18: - | D18: 1000 | E18: 0 | F18: =SUMIFS(F10:F17,O10:O17,">0") | G18: n/a | H18: =IF(G18="Tier 2",Assumptions!$B$46,IF(G18="Tier 1",Assumptions!$B$44,0)) | I18: =IF(G18="Tier 2",Assumptions!$B$47,IF(G18="Tier 1",Assumptions!$B$45,0)) | J18: 0 | K18: =F18*((D18*H18)+(E18*I18))/1000000*(1-J18) | L18: Embedding | M18: =IF(L18="Tier 1",Assumptions!$B$44+$B$7*Assumptions!$B$46,IF(L18="Tier 2",Assumptions!$B$46,IF(L18="Embedding",Assumptions!$B$48,0))) | N18: =IF(L18="Tier 1",Assumptions!$B$45+$B$7*Assumptions!$B$47,IF(L18="Tier 2",Assumptions!$B$47,0)) | O18: 0 | P18: =F18*((D18*M18)+(E18*N18))/1000000*(1-O18) | Q18: =K18-P18 | R18: 0 | S18: 0 | T18: One embedding per cacheable call (only exists in the optimized design).
A19: Total per month | K19: =SUM(K10:K18) | P19: =SUM(P10:P18) | Q19: =SUM(Q10:Q18) | R19: =SUM(R10:R18) | S19: =SUM(S10:S18)
A21: Summary (monthly, Year 1 volumes)
A22: Token_cost: baseline | B22: =K19
A23: Token_cost: optimized | B23: =P19
A24: Savings per month | B24: =Q19
A25: Token optimisation savings % | B25: =IF(K19=0,0,Q19/K19)
A26: Blended cache ratio, CR (optimized) | B26: =IF(R19=0,0,1-S19/R19)
A27: Tier 2 share of optimized cost | B27: =IF(P19=0,0,SUMIFS(P10:P18,L10:L18,"Tier 2")/P19)
A28: Tokens / sec: average (billed, optimized) | B28: =S19/(30*24*3600)
A29: Tokens / sec: peak (× peak factor) | B29: =B28*Assumptions!$B$37
A30: LLM cost per incident (optimized, incl. alert share) | B30: =IF($B$6=0,0,P19/$B$6)

Sheet TCO & ROI
A1: 3-Year TCO & ROI
A2: TCO = Compute_infra + Token_cost + Ops_overhead
A3: Formula as given in the Capstone brief, §4 Artifact 4. All $ figures are nominal; NPV discounts net benefit.
A4: Line item | B4: Year 1 | C4: Year 2 | D4: Year 3 | E4: 3-Year Total | F4: Formula / note
A5: Year index | B5: 1 | C5: 2 | D5: 3 | F5: Used as the exponent for growth / escalation.
A7: Volume
A8: Alerts per year | B8: =Assumptions!$B$20*12*(1+Assumptions!$B$24)^(B$5-1) | C8: =Assumptions!$B$20*12*(1+Assumptions!$B$24)^(C$5-1) | D8: =Assumptions!$B$20*12*(1+Assumptions!$B$24)^(D$5-1) | E8: =SUM(B8:D8) | F8: alerts/month × 12 × (1 + growth)^(year − 1)
A9: Incidents per year | B9: =Assumptions!$B$21*12*(1+Assumptions!$B$24)^(B$5-1) | C9: =Assumptions!$B$21*12*(1+Assumptions!$B$24)^(C$5-1) | D9: =Assumptions!$B$21*12*(1+Assumptions!$B$24)^(D$5-1) | E9: =SUM(B9:D9) | F9: incidents/month × 12 × (1 + growth)^(year − 1)
A10: P1 / P2 incidents per year | B10: =B9*Assumptions!$B$22 | C10: =C9*Assumptions!$B$22 | D10: =D9*Assumptions!$B$22 | E10: =SUM(B10:D10)
A11: Adoption ramp (share of estate on the platform) | B11: =Assumptions!$B$33 | C11: =Assumptions!$B$34 | D11: =Assumptions!$B$35
A12: Coverage: auto + HITL-assisted share of incidents | B12: =Assumptions!$E$9+Assumptions!$E$10 | C12: =Assumptions!$E$9+Assumptions!$E$10 | D12: =Assumptions!$E$9+Assumptions!$E$10 | F12: From the active scenario on Assumptions.
A14: Compute_infra
A15: Compute_infra | B15: =Assumptions!$E$60*12*(1+Assumptions!$B$39)^(B$5-1) | C15: =Assumptions!$E$60*12*(1+Assumptions!$B$39)^(C$5-1) | D15: =Assumptions!$E$60*12*(1+Assumptions!$B$39)^(D$5-1) | E15: =SUM(B15:D15) | F15: Monthly infra total (Assumptions §5) × 12 × (1 + infra growth)^(year − 1)
A17: Token_cost
A18: Token_cost (optimized: tiered routing + semantic cache) | B18: ='Token Economics'!$B$23*12*(1+Assumptions!$B$24)^(B$5-1)*B11 | C18: ='Token Economics'!$B$23*12*(1+Assumptions!$B$24)^(C$5-1)*C11 | D18: ='Token Economics'!$B$23*12*(1+Assumptions!$B$24)^(D$5-1)*D11 | E18: =SUM(B18:D18) | F18: Token Economics optimized total × 12 × volume growth × adoption
A19: Memo: Token_cost if baseline (all Tier 2, no cache) | B19: ='Token Economics'!$B$22*12*(1+Assumptions!$B$24)^(B$5-1)*B11 | C19: ='Token Economics'!$B$22*12*(1+Assumptions!$B$24)^(C$5-1)*C11 | D19: ='Token Economics'!$B$22*12*(1+Assumptions!$B$24)^(D$5-1)*D11 | E19: =SUM(B19:D19) | F19: Not part of TCO; shows what ADR 03 saves.
A20: Memo: token spend avoided by ADR 03 | B20: =B19-B18 | C20: =C19-C18 | D20: =D19-D18 | E20: =SUM(B20:D20)
A22: Ops_overhead
A23: Build & integration + security review (one-time) | B23: =Assumptions!$B$69*Assumptions!$B$70/12*Assumptions!$B$66+Assumptions!$B$71 | C23: =0 | D23: =0 | E23: =SUM(B23:D23) | F23: engineers × months/12 × FTE cost + security review; Year 1 only
A24: Platform operations FTE | B24: =Assumptions!$B$64*Assumptions!$B$66*(1+Assumptions!$B$67)^(B$5-1) | C24: =Assumptions!$B$64*Assumptions!$B$66*(1+Assumptions!$B$67)^(C$5-1) | D24: =Assumptions!$B$64*Assumptions!$B$66*(1+Assumptions!$B$67)^(D$5-1) | E24: =SUM(B24:D24)
A25: Model evaluation & guardrail / policy upkeep | B25: =Assumptions!$B$65*Assumptions!$B$66*(1+Assumptions!$B$67)^(B$5-1) | C25: =Assumptions!$B$65*Assumptions!$B$66*(1+Assumptions!$B$67)^(C$5-1) | D25: =Assumptions!$B$65*Assumptions!$B$66*(1+Assumptions!$B$67)^(D$5-1) | E25: =SUM(B25:D25)
A26: Observability & eval tooling licences | B26: =Assumptions!$B$68 | C26: =Assumptions!$B$68 | D26: =Assumptions!$B$68 | E26: =SUM(B26:D26)
A27: SRE time spent on HITL approvals | B27: =B9*B11*Assumptions!$E$10*Assumptions!$B$32/60*Assumptions!$B$31 | C27: =C9*C11*Assumptions!$E$10*Assumptions!$B$32/60*Assumptions!$B$31 | D27: =D9*D11*Assumptions!$E$10*Assumptions!$B$32/60*Assumptions!$B$31 | E27: =SUM(B27:D27) | F27: incidents × adoption × HITL share × minutes/60 × SRE rate
A28: Ops_overhead | B28: =SUM(B23:B27) | C28: =SUM(C23:C27) | D28: =SUM(D23:D27) | E28: =SUM(B28:D28)
A30: TCO = Compute_infra + Token_cost + Ops_overhead | B30: =B15+B18+B28 | C30: =C15+C18+C28 | D30: =D15+D18+D28 | E30: =SUM(B30:D30) | F30: Brief formula, per year
A32: Benefits
A33: Baseline downtime cost per P1/P2 incident | B33: =Assumptions!$B$23*Assumptions!$B$27*Assumptions!$E$12+(1-Assumptions!$B$23)*Assumptions!$B$28*Assumptions!$E$12*Assumptions!$B$29 | C33: =Assumptions!$B$23*Assumptions!$B$27*Assumptions!$E$12+(1-Assumptions!$B$23)*Assumptions!$B$28*Assumptions!$E$12*Assumptions!$B$29 | D33: =Assumptions!$B$23*Assumptions!$B$27*Assumptions!$E$12+(1-Assumptions!$B$23)*Assumptions!$B$28*Assumptions!$E$12*Assumptions!$B$29 | F33: P1 share × P1 MTTR × $/h + P2 share × P2 MTTR × $/h × P2 factor
A34: Downtime avoided (faster MTTR on P1/P2) | B34: =B10*B11*B12*B33*Assumptions!$E$11*Assumptions!$E$13 | C34: =C10*C11*C12*C33*Assumptions!$E$11*Assumptions!$E$13 | D34: =D10*D11*D12*D33*Assumptions!$E$11*Assumptions!$E$13 | E34: =SUM(B34:D34) | F34: P1/P2 incidents × adoption × coverage × downtime $/incident × MTTR reduction × attribution
A35: Responder toil avoided | B35: =B9*B11*B12*Assumptions!$B$30*Assumptions!$E$14*Assumptions!$B$31*Assumptions!$E$16 | C35: =C9*C11*C12*Assumptions!$B$30*Assumptions!$E$14*Assumptions!$B$31*Assumptions!$E$16 | D35: =D9*D11*D12*Assumptions!$B$30*Assumptions!$E$14*Assumptions!$B$31*Assumptions!$E$16 | E35: =SUM(B35:D35) | F35: incidents × adoption × coverage × responder hours × toil reduction × SRE rate × realisation
A36: Alert-triage time avoided (alert fatigue) | B36: =B8*B11*Assumptions!$B$25*Assumptions!$B$26/60*Assumptions!$E$15*Assumptions!$B$31*Assumptions!$E$16 | C36: =C8*C11*Assumptions!$B$25*Assumptions!$B$26/60*Assumptions!$E$15*Assumptions!$B$31*Assumptions!$E$16 | D36: =D8*D11*Assumptions!$B$25*Assumptions!$B$26/60*Assumptions!$E$15*Assumptions!$B$31*Assumptions!$E$16 | E36: =SUM(B36:D36) | F36: alerts × adoption × human-reviewed share × minutes/60 × auto-triage share × SRE rate × realisation
A37: Total benefits | B37: =SUM(B34:B36) | C37: =SUM(C34:C36) | D37: =SUM(D34:D36) | E37: =SUM(B37:D37)
A39: Returns
A40: Net benefit (Benefits − TCO) | B40: =B37-B30 | C40: =C37-C30 | D40: =D37-D30 | E40: =SUM(B40:D40)
A41: Cumulative net benefit | B41: =B40 | C41: =B41+C40 | D41: =C41+D40
A42: TCO per incident handled | B42: =IF(B9=0,0,B30/B9) | C42: =IF(C9=0,0,C30/C9) | D42: =IF(D9=0,0,D30/D9)
A44: Headline KPIs (active scenario)
A45: 3-year ROI = (Σ Benefits − Σ TCO) / Σ TCO | B45: =IF(E30=0,0,(E37-E30)/E30)
A46: NPV of net benefit @ discount rate | B46: =NPV(Assumptions!$B$36,B40:D40)
A47: Benefit-to-cost ratio | B47: =IF(E30=0,0,E37/E30)
A48: Payback period (months, even monthly spread within a year) | B48: =IF(B41>=0,IF(B37=0,0,12*B30/B37),IF(C41>=0,12+12*(-B41)/C40,IF(D41>=0,24+12*(-C41)/D40,"> 36")))
...

Sheet NFR SLA Matrix
A1: NFR SLA Matrix
A2: Measured values come from the real-model run (OpenAI gpt-4o-mini / gpt-4o via LiteLLM, simulated clusters, 2026-09-28T13:04:21+00:00); guardrail-block evidence from the MockLLM run (2026-09-28T10:09:27+00:00), whose compromised-planner step is simulated.
A4: # | B4: NFR | C4: Metric (symbol) | D4: Target | E4: Target value | F4: Test | G4: Measured | H4: Unit | I4: Status | J4: Evidence / how measured | K4: Production control
A5: 1 | B5: End-to-end latency per agent step | C5: T_lat (p95) | D5: p95 < 3.5 s (brief) | E5: 3.5 | F5: <= | G5: 4.386 | H5: s | I5: =IF(G5="","NOT MEASURED",IF(F5="<=",IF(G5<=E5,"MET","NOT MET"),IF(F5=">=",IF(G5>=E5,"MET","NOT MET"),IF(G5=E5,"MET","NOT MET")))) | J5: p95 across agent steps, real OpenAI run. Slowest steps (avg): planner 4.0 s (Tier 2), verifier 3.4 s, intake 2.7 s. | K5: Pilot fix: take the verifier's LLM call off the critical path (its verdict is not authoritative), stream Tier-2 output, keep intake on Tier 1 without escalation
A6: 2 | B6: Platform availability | C6: A | D6: 99.9% (brief) | E6: 0.999 | F6: >= | H6: % | I6: =IF(G6="","NOT MEASURED",IF(F6="<=",IF(G6<=E6,"MET","NOT MET"),IF(F6=">=",IF(G6>=E6,"MET","NOT MET"),IF(G6=E6,"MET","NOT MET")))) | J6: Not measurable in a prototype. Error budget at target: see row below the table. | K6: 3 stateless orchestrator replicas, multi-AZ Redis/Postgres, LLM provider fallback, break-glass runbook
A7: 3 | B7: LLM throughput headroom | C7: Tokens/sec (peak) | D7: Peak ≤ provisioned quota | E7: =Assumptions!$B$40 | F7: <= | G7: ='Token Economics'!$B$29 | H7: tokens/s | I7: =IF(G7="","NOT MEASURED",IF(F7="<=",IF(G7<=E7,"MET","NOT MET"),IF(F7=">=",IF(G7>=E7,"MET","NOT MET"),IF(G7=E7,"MET","NOT MET")))) | J7: Projected peak from Token Economics vs. quota on Assumptions. | K7: Provider rate-limit request; queue + back-pressure in Supervisor
A8: 4 | B8: Cache effectiveness | C8: CR | D8: ≥ 35% (ADR 03) | E8: 0.35 | F8: >= | G8: 0.33 | H8: % | I8: =IF(G8="","NOT MEASURED",IF(F8="<=",IF(G8<=E8,"MET","NOT MET"),IF(F8=">=",IF(G8>=E8,"MET","NOT MET"),IF(G8=E8,"MET","NOT MET")))) | J8: Demo mix of 6 incidents; only repeated incidents can hit. Projected blended CR in Token Economics. | K8: Similarity ≥ 0.92, scoped keys, TTL 15 min; alert on reopened cache-hit incidents
A9: 5 | B9: Tool reliability (raw) | C9: FR | D9: ≤ 2% | E9: 0.02 | F9: <= | G9: 0.08 | H9: % | I9: =IF(G9="","NOT MEASURED",IF(F9="<=",IF(G9<=E9,"MET","NOT MET"),IF(F9=">=",IF(G9>=E9,"MET","NOT MET"),IF(G9=E9,"MET","NOT MET")))) | J9: Failures were injected on purpose (simulated kube-apiserver timeouts) to exercise retry. | K9: Retry with backoff + per-tool circuit breaker (3 failures / 30 s)
A10: 6 | B10: Tool reliability (after retry) | C10: Unrecovered tool failures | D10: 0 | E10: 0 | F10: <= | G10: 0 | H10: count | I10: =IF(G10="","NOT MEASURED",IF(F10="<=",IF(G10<=E10,"MET","NOT MET"),IF(F10=">=",IF(G10>=E10,"MET","NOT MET"),IF(G10=E10,"MET","NOT MET")))) | J10: All injected transient failures recovered on retry; every incident reached a terminal state. | K10: Escalate to on-call when the breaker opens
A11: 7 | B11: HITL trigger on low confidence | C11: C | D11: Human if C < 0.85 (brief) | E11: 0.85 | F11: = | G11: 0.85 | H11: threshold | I11: =IF(G11="","NOT MEASURED",IF(F11="<=",IF(G11<=E11,"MET","NOT MET"),IF(F11=">=",IF(G11>=E11,"MET","NOT MET"),IF(G11=E11,"MET","NOT MET")))) | J11: Configured threshold (config.hitl_confidence_threshold); test_non_destructive_action_needs_human_when_confidence_below_085. | K11: Threshold under change control; audited per decision
A12: 8 | B12: Destructive actions gated by SRE | C12: % destructive actions paused | D12: 100% | E12: 1 | F12: >= | G12: 1 | H12: % | I12: =IF(G12="","NOT MEASURED",IF(F12="<=",IF(G12<=E12,"MET","NOT MET"),IF(F12=">=",IF(G12>=E12,"MET","NOT MET"),IF(G12=E12,"MET","NOT MET")))) | J12: 4/4 DESTRUCTIVE actions in the demo paused for approval; executor only reachable via HITL gate (test). | K12: Signed single-use approval token enforced in MCP server
A13: 9 | B13: Command-injection guardrail | C13: % malicious plans blocked | D13: 100% | E13: 1 | F13: >= | G13: 1 | H13: % | I13: =IF(G13="","NOT MEASURED",IF(F13="<=",IF(G13<=E13,"MET","NOT MET"),IF(F13=">=",IF(G13>=E13,"MET","NOT MET"),IF(G13=E13,"MET","NOT MET")))) | J13: 1/1 simulated malicious plan blocked (MockLLM run); 13/13 deny-list patterns (incl. exfiltration) in unit tests; see ADR 04. | K13: Deny-list + OPA policy + dry-run inside MCP server (ADR 04, L3)
A14: 10 | B14: Prompt-injection guardrail | C14: % injected lines quarantined | D14: 100% | E14: 1 | F14: >= | G14: 1 | H14: % | I14: =IF(G14="","NOT MEASURED",IF(F14="<=",IF(G14<=E14,"MET","NOT MET"),IF(F14=">=",IF(G14>=E14,"MET","NOT MET"),IF(G14=E14,"MET","NOT MET")))) | J14: 2/2 injected log lines quarantined in the prompt-injection scenario. | K14: Add LlamaGuard 3 / Guardrails AI as ML layer (L2)
A15: 11 | B15: Audit compliance | C15: Audit chain integrity | D15: 100% valid | E15: 1 | F15: >= | G15: 1 | H15: % | I15: =IF(G15="","NOT MEASURED",IF(F15="<=",IF(G15<=E15,"MET","NOT MET"),IF(F15=">=",IF(G15>=E15,"MET","NOT MET"),IF(G15=E15,"MET","NOT MET")))) | J15: Hash chain verified over 115 records; tamper test in unit tests. | K15: Ship to S3 Object Lock (WORM) + SIEM
A16: 12 | B16: Token optimisation savings | C16: Savings vs. all-Tier-2 | D16: ≥ 50% (ADR 03) | E16: 0.5 | F16: >= | G16: ='Token Economics'!$B$25 | H16: % | I16: =IF(G16="","NOT MEASURED",IF(F16="<=",IF(G16<=E16,"MET","NOT MET"),IF(F16=">=",IF(G16>=E16,"MET","NOT MET"),IF(G16=E16,"MET","NOT MET")))) | J16: Projected from Token Economics (routing + cache). | K16: Weekly Tier-1 vs Tier-2 eval; cache hit dashboard
A17: 13 | B17: LLM cost per incident | C17: $ / incident | D17: ≤ $1.00 | E17: 1 | F17: <= | G17: ='Token Economics'!$B$30 | H17: $ | I17: =IF(G17="","NOT MEASURED",IF(F17="<=",IF(G17<=E17,"MET","NOT MET"),IF(F17=">=",IF(G17>=E17,"MET","NOT MET"),IF(G17=E17,"MET","NOT MET")))) | J17: Real run: $0.034 for 6 incidents ($0.0057 each) on 7-line demo logs; projection assumes production-size logs. | K17: Per-incident token budget in Supervisor (60k tokens)
A18: 14 | B18: HITL approval turnaround | C18: p50 SRE response | D18: ≤ 10 min | E18: 10 | F18: <= | H18: min | I18: =IF(G18="","NOT MEASURED",IF(F18="<=",IF(G18<=E18,"MET","NOT MET"),IF(F18=">=",IF(G18>=E18,"MET","NOT MET"),IF(G18=E18,"MET","NOT MET")))) | J18: Approvals were scripted in the demo; measure in pilot from hitl.requested → hitl.approved audit events. | K18: Slack/Teams approval card, 15-min token expiry, auto-escalation
B20: Error budget at availability target | G20: =(1-E6)*30*24*60 | H20: min / month | J20: (1 − 0.999) × 30 days × 24 h × 60 min
B21: Status count | C21: MET | G21: =COUNTIF($I$5:$I$18,C21)
C22: NOT MET | G22: =COUNTIF($I$5:$I$18,C22)
C23: NOT MEASURED | G23: =COUNTIF($I$5:$I$18,C23)
